Workbook

Sheet Cover
B9: Tesla
B10: Company analysis

Sheet Drivers
B1: Drivers
B3: Selected case | C3: 2
B4: Company | C4: Tesla
B5: Currency | C5: USD
B6: Domestic country | C6: United States
B7: 10-year treasury yield ( 08.06.2026) | C7: 0.0455
B8: Market risk premium US | C8: 0.055
B9: Company beta ( 08.06.2026) | C9: 1.18
B10: Tesla share price ( 08.06.2026) | C10: 408.95
B11: Bond Yield (Mar 19 2030) | C11: 0.0545
B12: Corporate tax rate | C12: 0.21
B13: Expected inflation | C13: 0.031
B14: No. of Shares (million) | C14: 3752.43

Sheet Input ->
B14: Input -->

Sheet P&L Input
B1: P&L Input
B3: ($ millions) | C3: 2021 Act | D3: 2022 Act | E3: 2023 Act | F3: 2024 Act | G3: 2025 Act
B4: Automotive revenues | C4: 47232 | D4: 71462 | E4: 82419 | F4: 77070 | G4: 69526
B5: Energy generation and storage | C5: 2789 | D5: 3909 | E5: 6035 | F5: 10086 | G5: 12771
B6: Services and other | C6: 3802 | D6: 6091 | E6: 8319 | F6: 10534 | G6: 12530
B7: Total revenues | C7: =SUM(C4:C6) -> 53823 | D7: =SUM(D4:D6) -> 81462 | E7: =SUM(E4:E6) -> 96773 | F7: =SUM(F4:F6) -> 97690 | G7: =SUM(G4:G6) -> 94827
B8: Automotive cost of revenues | C8: -33393 | D8: -51108 | E8: -66389 | F8: -62873 | G8: -57165
B9: Energy generation and storage cost of revenues | C9: -2918 | D9: -3621 | E9: -4894 | F9: -7446 | G9: -8969
B10: Services and other cost of revenues | C10: -3906 | D10: -5880 | E10: -7830 | F10: -9921 | G10: -11599
B11: Gross profit | C11: =SUM(C7:C10) -> 13606 | D11: =SUM(D7:D10) -> 20853 | E11: =SUM(E7:E10) -> 17660 | F11: =SUM(F7:F10) -> 17450 | G11: =SUM(G7:G10) -> 17094
B12: Research and development | C12: -2593 | D12: -3075 | E12: -3969 | F12: -4540 | G12: -6411
B13: Selling, general and administrative | C13: -4517 | D13: -3946 | E13: -4800 | F13: -5150 | G13: -5834
B14: Restructuring and other | C14: 27 | D14: -176 | F14: -684 | G14: -494
B15: EBIT | C15: =SUM(C11:C14) -> 6523 | D15: =SUM(D11:D14) -> 13656 | E15: =SUM(E11:E14) -> 8891 | F15: =SUM(F11:F14) -> 7076 | G15: =SUM(G11:G14) -> 4355
B16: Interest income | C16: 56 | D16: 297 | E16: 1066 | F16: 1569 | G16: 1680
B17: Interest expense | C17: -371 | D17: -191 | E17: -156 | F17: -350 | G17: -338
B18: Other income (expense), net | C18: 135 | D18: -43 | E18: 172 | F18: 695 | G18: -419
B19: EBT | C19: =SUM(C15:C18) -> 6343 | D19: =SUM(D15:D18) -> 13719 | E19: =SUM(E15:E18) -> 9973 | F19: =SUM(F15:F18) -> 8990 | G19: =SUM(G15:G18) -> 5278
B20: Provision for income taxes | C20: -699 | D20: -1132 | E20: 5001 | F20: -1837 | G20: -1423
B21: Net income incl. minority interests | C21: =SUM(C19:C20) -> 5644 | D21: =SUM(D19:D20) -> 12587 | E21: =SUM(E19:E20) -> 14974 | F21: =SUM(F19:F20) -> 7153 | G21: =SUM(G19:G20) -> 3855
B22: Minority interests | C22: -125 | D22: -31 | E22: 23 | F22: -62 | G22: -61
B23: Net income | C23: =SUM(C21:C22) -> 5519 | D23: =SUM(D21:D22) -> 12556 | E23: =SUM(E21:E22) -> 14997 | F23: =SUM(F21:F22) -> 7091 | G23: =SUM(G21:G22) -> 3794
B25: KPIs
B26: Revenue % automotive y-o-y | D26: =D4/C4-1 -> 0.51299966 | E26: =E4/D4-1 -> 0.15332624 | F26: =F4/E4-1 -> -0.064900084 | G26: =G4/F4-1 -> -0.09788504
B27: Revenue % generation y-o-y | D27: =D5/C5-1 -> 0.40157763 | E27: =E5/D5-1 -> 0.54387311 | F27: =F5/E5-1 -> 0.67125104 | G27: =G5/F5-1 -> 0.26621059
B28: Revenue % services y-o-y | D28: =D6/C6-1 -> 0.60205155 | E28: =E6/D6-1 -> 0.36578559 | F28: =F6/E6-1 -> 0.26625796 | G28: =G6/F6-1 -> 0.18948168
B29: GP% automotive | C29: =(C4+C8)/C4 -> 0.29300051 | D29: =(D4+D8)/D4 -> 0.2848227 | E29: =(E4+E8)/E4 -> 0.19449399 | F29: =(F4+F8)/F4 -> 0.18420916 | G29: =(G4+G8)/G4 -> 0.1777896
B30: GP% energy generation and automotive | C30: =(C5+C9)/C5 -> -0.046253137 | D30: =(D5+D9)/D5 -> 0.073676132 | E30: =(E5+E9)/E5 -> 0.18906379 | F30: =(F5+F9)/F5 -> 0.26174896 | G30: =(G5+G9)/G5 -> 0.29770574
B31: GP% services and other | C31: =(C6+C10)/C6 -> -0.027354024 | D31: =(D6+D10)/D6 -> 0.034641274 | E31: =(E6+E10)/E6 -> 0.058781103 | F31: =(F6+F10)/F6 -> 0.058192519 | G31: =(G6+G10)/G6 -> 0.074301676
B32: Overall GP% | C32: =(SUM(C4:C6)+SUM(C8:C10))/SUM(C4:C6) -> 0.25279156 | D32: =(SUM(D4:D6)+SUM(D8:D10))/SUM(D4:D6) -> 0.25598439 | E32: =(SUM(E4:E6)+SUM(E8:E10))/SUM(E4:E6) -> 0.18248892 | F32: =(SUM(F4:F6)+SUM(F8:F10))/SUM(F4:F6) -> 0.17862627 | G32: =(SUM(G4:G6)+SUM(G8:G10))/SUM(G4:G6) -> 0.18026511
B33: EBIT % | C33: =C15/C7 -> 0.12119354 | D33: =D15/D7 -> 0.16763644 | E33: =E15/E7 -> 0.0918748 | F33: =F15/F7 -> 0.072433207 | G33: =G15/G7 -> 0.045925738
B34: Net loss % | C34: =C23/C7 -> 0.10253981 | D34: =D23/D7 -> 0.15413322 | E34: =E23/E7 -> 0.15497091 | F34: =F23/F7 -> 0.072586754 | G34: =G23/G7 -> 0.040009702
B35: ROA | C35: =C23/'Balance Sheet Input'!C20 -> 0.088828443 | D35: =D23/'Balance Sheet Input'!D20 -> 0.15249338 | E35: =E23/'Balance Sheet Input'!E20 -> 0.14066105 | F35: =F23/'Balance Sheet Input'!F20 -> 0.058089621 | G35: =G23/'Balance Sheet Input'!G20 -> 0.027531457
B36: ROE | C36: =C23/'Balance Sheet Input'!C35 -> 0.18281493 | D36: =D23/'Balance Sheet Input'!D35 -> 0.28086972 | E36: =E23/'Balance Sheet Input'!E35 -> 0.23943864 | F36: =F23/'Balance Sheet Input'!F35 -> 0.09725289 | G36: =G23/'Balance Sheet Input'!G35 -> 0.04619112

Sheet Balance Sheet Input
B1: Balance Sheet Input
B3: ($ millions) | C3: 2021 Act | D3: 2022 Act | E3: 2023 Act | F3: 2024 Act | G3: 2025 Act
B4: Cash and cash equivalents | C4: 17576 | D4: 16253 | E4: 16398 | F4: 16139 | G4: 16513
B5: Accounts receivable, net | C5: 1913 | D5: 2952 | E5: 3508 | F5: 4418 | G5: 4576
B6: Inventory | C6: 5757 | D6: 12839 | E6: 13626 | F6: 12017 | G6: 12392
B7: Prepaid expenses and other current assets | C7: 1723 | D7: 2941 | E7: 3388 | F7: 5362 | G7: 7615
B8: Short-term investments | C8: 131 | D8: 5932 | E8: 12696 | F8: 20424 | G8: 27546
B9: Total current assets | C9: =SUM(C4:C8) -> 27100 | D9: =SUM(D4:D8) -> 40917 | E9: =SUM(E4:E8) -> 49616 | F9: =SUM(F4:F8) -> 58360 | G9: =SUM(G4:G8) -> 68642
B11: Operating lease vehicles, net | C11: 4511 | D11: 5035 | E11: 5989 | F11: 5581 | G11: 4912
B12: Solar energy systems, leased and to be leased, net | C12: 5765 | D12: 5489 | E12: 5229 | F12: 4924 | G12: 4604
B13: Property, plant and equipment, net | C13: 18884 | D13: 23548 | E13: 29725 | F13: 35836 | G13: 40643
B14: Operating lease right-of-use assets | C14: 2016 | D14: 2563 | E14: 4180 | F14: 5160 | G14: 6027
B15: Intangible assets, net | C15: 257 | D15: 215 | E15: 178 | F15: 1076 | G15: 1008
B16: Deferred tax assets | C16: 0 | D16: 328 | E16: 6733 | F16: 6524 | G16: 6925
B17: Good will | C17: 200 | D17: 194 | E17: 253 | F17: 0 | G17: 0
B18: Digital assets,net | C18: 1260 | D18: 184 | E18: 184 | F18: 0 | G18: 0
B19: Other assets | C19: 2138 | D19: 3865 | E19: 4531 | F19: 4609 | G19: 5045
B20: Total assets | C20: =SUM(C9:C19) -> 62131 | D20: =SUM(D9:D19) -> 82338 | E20: =SUM(E9:E19) -> 106618 | F20: =SUM(F9:F19) -> 122070 | G20: =SUM(G9:G19) -> 137806
B22: Accounts payable | C22: 10025 | D22: 15255 | E22: 14431 | F22: 12474 | G22: 13371
B23: Accrued liabilities | C23: 5719 | D23: 8205 | E23: 9080 | F23: 10723 | G23: 13279
B24: Deferred revenue | C24: 1447 | D24: 1747 | E24: 2864 | F24: 3168 | G24: 3424
B25: customer deposite | C25: 925 | D25: 0 | E25: 0 | F25: 0 | G25: 0
B26: Current portion of long-term debt and capital leases | C26: 1589 | D26: 1502 | E26: 2373 | F26: 2456 | G26: 1640
B27: Total current liabilities | C27: =SUM(C22:C26) -> 19705 | D27: =SUM(D22:D26) -> 26709 | E27: =SUM(E22:E26) -> 28748 | F27: =SUM(F22:F26) -> 28821 | G27: =SUM(G22:G26) -> 31714
B29: Long-term debt and capital leases, net of current
B30: portion | C30: 5245 | D30: 1597 | E30: 2857 | F30: 5757 | G30: 6736
B31: Other liabilities | C31: 3546 | D31: 5330 | E31: 8153 | F31: 10495 | G31: 12860
B32: Deferred revenue, net of current portion | C32: 2052 | D32: 2804 | E32: 3251 | F32: 3317 | G32: 3631
B33: Total liabilities | C33: =SUM(C27:C32) -> 30548 | D33: =SUM(D27:D32) -> 36440 | E33: =SUM(E27:E32) -> 43009 | F33: =SUM(F27:F32) -> 48390 | G33: =SUM(G27:G32) -> 54941
B34: Redeemable noncontrolling interests in subsidiaries | C34: 568 | D34: 409 | E34: 242 | F34: 63 | G34: 58
B35: Total stockholders' equity | C35: 30189 | D35: 44704 | E35: 62634 | F35: 72913 | G35: 82137
B36: Noncontrolling interests in subsidiaries | C36: 826 | D36: 785 | E36: 733 | F36: 704 | G36: 670
B37: Total liabilities and equity | C37: =C33+C35+C36+C34 -> 62131 | D37: =D33+D35+D36+D34 -> 82338 | E37: =E33+E35+E36+E34 -> 106618 | F37: =F33+F35+F36+F34 -> 122070 | G37: =G33+G35+G36+G34 -> 137806
B39: KPIs
B40: Liquidity ratios
B41: Quick ratio | C41: =C4/C27 -> 0.89195636 | D41: =D4/D27 -> 0.60852147 | E41: =E4/E27 -> 0.5704049 | F41: =F4/F27 -> 0.55997363 | G41: =G4/G27 -> 0.52068487
B42: Current ratio | C42: =C9/C27 -> 1.3752855 | D42: =D9/D27 -> 1.5319555 | E42: =E9/E27 -> 1.725894 | F42: =F9/F27 -> 2.0249124 | G42: =G9/G27 -> 2.1644069
B43: DSO | C43: =C5/'P&L Input'!C7*360 -> 12.795273 | D43: =D5/'P&L Input'!D7*360 -> 13.045592 | E43: =E5/'P&L Input'!E7*360 -> 13.049921 | F43: =F5/'P&L Input'!F7*360 -> 16.280889 | G43: =G5/'P&L Input'!G7*360 -> 17.372267
B44: DIO | C44: =-C6/SUM('P&L Input'!C8:C10)*360 -> 51.533431 | D44: =-D6/SUM('P&L Input'!D8:D10)*360 -> 76.259961 | E44: =-E6/SUM('P&L Input'!E8:E10)*360 -> 62.004475 | F44: =-F6/SUM('P&L Input'!F8:F10)*360 -> 53.914756 | G44: =-G6/SUM('P&L Input'!G8:G10)*360 -> 57.390298
B45: DPO | C45: =-C22/SUM('P&L Input'!C8:C10)*360 -> 89.73817 | D45: =-D22/SUM('P&L Input'!D8:D10)*360 -> 90.610305 | E45: =-E22/SUM('P&L Input'!E8:E10)*360 -> 65.667589 | F45: =-F22/SUM('P&L Input'!F8:F10)*360 -> 55.965105 | G45: =-G22/SUM('P&L Input'!G8:G10)*360 -> 61.924279
...

Sheet Workings ->
B14: Workings -->

Sheet Income Statement items
B14: Income Statement items

Sheet Automotive
B14: Automotive

Sheet Deliveries
B1: Deliveries
B3: ($ millions) | C3: Tesla Deliveries
B4: Vehicle | C4: 2021 Act | D4: 2022 Act | E4: 2023 Act | F4: 2024 Act | G4: 2025 Act | H4: 2026 Fcst | I4: 2027 Fcst | J4: 2028 Fcst | K4: 2029 Fcst | L4: 2030 Fcst | M4: 2031 Fcst | N4: 2032 Fcst | O4: 2033 Fcst | P4: 2034 Fcst | Q4: 2035 Fcst
B5: Tesla Model 3 | C5: 500000 | D5: 530000 | E5: 500000 | F5: 480000 | G5: 450000 | H5: =H24 -> 450000 | I5: =I24 -> 450000 | J5: =J24 -> 500000 | K5: =K24 -> 550000 | L5: =L24 -> 600000 | M5: =M24 -> 650000 | N5: =N24 -> 700000 | O5: =O24 -> 750000 | ... Q5: =Q24 -> 850000
B6: Tesla Model S and X | C6: 50000 | D6: 67000 | E6: 69000 | F6: 56000 | G6: 50000 | H6: =H25 -> 40000 | I6: =I25 -> 20000 | J6: =J25 -> 10000 | K6: =K25 -> 0 | L6: =L25 -> 0 | M6: =M25 -> 0 | N6: =N25 -> 0 | O6: =O25 -> 0 | ... Q6: =Q25 -> 0
B7: Tesla Model Y | C7: 411000 | D7: 717000 | E7: 1140000 | F7: 1124000 | G7: 1130000 | H7: =H26 -> 1200000 | I7: =I26 -> 1350000 | J7: =J26 -> 1500000 | K7: =K26 -> 1650000 | L7: =L26 -> 1850000 | M7: =M26 -> 2000000 | N7: =N26 -> 2150000 | O7: =O26 -> 2300000 | ... Q7: =Q26 -> 2600000
B8: Tesla Cybertruck | E8: 900 | F8: 19000 | G8: 50000 | H8: =H27 -> 75000 | I8: =I27 -> 120000 | J8: =J27 -> 180000 | K8: =K27 -> 250000 | L8: =L27 -> 300000 | M8: =M27 -> 350000 | N8: =N27 -> 400000 | O8: =O27 -> 450000 | ... Q8: =Q27 -> 550000
B9: Tesla Semi | C9: 0 | D9: 90 | E9: 180 | F9: 290 | G9: 5000 | H9: =H28 -> 10000 | I9: =I28 -> 20000 | J9: =J28 -> 35000 | K9: =K28 -> 50000 | L9: =L28 -> 75000 | M9: =M28 -> 100000 | N9: =N28 -> 125000 | O9: =O28 -> 150000 | ... Q9: =Q28 -> 200000
B10: Total | C10: =SUM(C5:C9) -> 961000 | D10: =SUM(D5:D9) -> 1314090 | E10: =SUM(E5:E9) -> 1710080 | F10: =SUM(F5:F9) -> 1679290 | G10: =SUM(G5:G9) -> 1685000 | H10: =SUM(H5:H9) -> 1775000 | I10: =SUM(I5:I9) -> 1960000 | J10: =SUM(J5:J9) -> 2225000 | ... Q10: =SUM(Q5:Q9) -> 4200000
B12: y-o-y growth %
B14: Tesla Model 3 | C14: n.a. | D14: =D5/C5-1 -> 0.06 | E14: =E5/D5-1 -> -0.056603774 | F14: =F5/E5-1 -> -0.04 | G14: =G5/F5-1 -> -0.0625 | H14: =H5/G5-1 -> 0 | I14: =I5/H5-1 -> 0 | J14: =J5/I5-1 -> 0.11111111 | K14: =K5/J5-1 -> 0.1 | ... Q14: =Q5/P5-1 -> 0.0625
B15: Tesla Model S and X | C15: n.a. | D15: =D6/C6-1 -> 0.34 | E15: =E6/D6-1 -> 0.029850746 | F15: =F6/E6-1 -> -0.1884058 | G15: =G6/F6-1 -> -0.10714286 | H15: =H6/G6-1 -> -0.2 | I15: =I6/H6-1 -> -0.5 | J15: =J6/I6-1 -> -0.5 | K15: n.a. | L15: n.a. | M15: n.a. | N15: n.a. | O15: n.a. | P15: n.a. | Q15: n.a.
B16: Tesla Model Y | C16: n.a. | D16: =D7/C7-1 -> 0.74452555 | E16: =E7/D7-1 -> 0.58995816 | F16: =F7/E7-1 -> -0.014035088 | G16: =G7/F7-1 -> 0.0053380783 | H16: =H7/G7-1 -> 0.061946903 | I16: =I7/H7-1 -> 0.125 | J16: =J7/I7-1 -> 0.11111111 | K16: =K7/J7-1 -> 0.1 | ... Q16: =Q7/P7-1 -> 0.06122449
B17: Tesla Cybertruck | C17: n.a. | D17: n.a. | E17: n.a. | F17: =F8/E8-1 -> 20.111111 | G17: =G8/F8-1 -> 1.6315789 | H17: =H8/G8-1 -> 0.5 | I17: =I8/H8-1 -> 0.6 | J17: =J8/I8-1 -> 0.5 | K17: =K8/J8-1 -> 0.38888889 | L17: =L8/K8-1 -> 0.2 | M17: =M8/L8-1 -> 0.16666667 | ... Q17: =Q8/P8-1 -> 0.1
B18: Tesla Semi | C18: n.a. | D18: n.a. | E18: =E9/D9-1 -> 1 | F18: =F9/E9-1 -> 0.61111111 | G18: =G9/F9-1 -> 16.241379 | H18: =H9/G9-1 -> 1 | I18: =I9/H9-1 -> 1 | J18: =J9/I9-1 -> 0.75 | K18: =K9/J9-1 -> 0.42857143 | L18: =L9/K9-1 -> 0.5 | ... Q18: =Q9/P9-1 -> 0.14285714
B23: Selected case
B24: Tesla Model 3 | H24: =CHOOSE(Drivers!$C$3,H31,H38,H45) -> 450000 | I24: =CHOOSE(Drivers!$C$3,I31,I38,I45) -> 450000 | J24: =CHOOSE(Drivers!$C$3,J31,J38,J45) -> 500000 | K24: =CHOOSE(Drivers!$C$3,K31,K38,K45) -> 550000 | L24: =CHOOSE(Drivers!$C$3,L31,L38,L45) -> 600000 | M24: =CHOOSE(Drivers!$C$3,M31,M38,M45) -> 650000 | N24: =CHOOSE(Drivers!$C$3,N31,N38,N45) -> 700000 | O24: =CHOOSE(Drivers!$C$3,O31,O38,O45) -> 750000 | ... Q24: =CHOOSE(Drivers!$C$3,Q31,Q38,Q45) -> 850000
B25: Tesla Model S and X | H25: =CHOOSE(Drivers!$C$3,H32,H39,H46) -> 40000 | I25: =CHOOSE(Drivers!$C$3,I32,I39,I46) -> 20000 | J25: =CHOOSE(Drivers!$C$3,J32,J39,J46) -> 10000 | K25: =CHOOSE(Drivers!$C$3,K32,K39,K46) -> 0 | L25: =CHOOSE(Drivers!$C$3,L32,L39,L46) -> 0 | M25: =CHOOSE(Drivers!$C$3,M32,M39,M46) -> 0 | N25: =CHOOSE(Drivers!$C$3,N32,N39,N46) -> 0 | O25: =CHOOSE(Drivers!$C$3,O32,O39,O46) -> 0 | ... Q25: =CHOOSE(Drivers!$C$3,Q32,Q39,Q46) -> 0
B26: Tesla Model Y | H26: =CHOOSE(Drivers!$C$3,H33,H40,H47) -> 1200000 | I26: =CHOOSE(Drivers!$C$3,I33,I40,I47) -> 1350000 | J26: =CHOOSE(Drivers!$C$3,J33,J40,J47) -> 1500000 | K26: =CHOOSE(Drivers!$C$3,K33,K40,K47) -> 1650000 | L26: =CHOOSE(Drivers!$C$3,L33,L40,L47) -> 1850000 | M26: =CHOOSE(Drivers!$C$3,M33,M40,M47) -> 2000000 | N26: =CHOOSE(Drivers!$C$3,N33,N40,N47) -> 2150000 | O26: =CHOOSE(Drivers!$C$3,O33,O40,O47) -> 2300000 | ... Q26: =CHOOSE(Drivers!$C$3,Q33,Q40,Q47) -> 2600000
B27: Tesla Cybertruck | H27: =CHOOSE(Drivers!$C$3,H34,H41,H48) -> 75000 | I27: =CHOOSE(Drivers!$C$3,I34,I41,I48) -> 120000 | J27: =CHOOSE(Drivers!$C$3,J34,J41,J48) -> 180000 | K27: =CHOOSE(Drivers!$C$3,K34,K41,K48) -> 250000 | L27: =CHOOSE(Drivers!$C$3,L34,L41,L48) -> 300000 | M27: =CHOOSE(Drivers!$C$3,M34,M41,M48) -> 350000 | N27: =CHOOSE(Drivers!$C$3,N34,N41,N48) -> 400000 | O27: =CHOOSE(Drivers!$C$3,O34,O41,O48) -> 450000 | ... Q27: =CHOOSE(Drivers!$C$3,Q34,Q41,Q48) -> 550000
B28: Tesla Semi | H28: =CHOOSE(Drivers!$C$3,H35,H42,H49) -> 10000 | I28: =CHOOSE(Drivers!$C$3,I35,I42,I49) -> 20000 | J28: =CHOOSE(Drivers!$C$3,J35,J42,J49) -> 35000 | K28: =CHOOSE(Drivers!$C$3,K35,K42,K49) -> 50000 | L28: =CHOOSE(Drivers!$C$3,L35,L42,L49) -> 75000 | M28: =CHOOSE(Drivers!$C$3,M35,M42,M49) -> 100000 | N28: =CHOOSE(Drivers!$C$3,N35,N42,N49) -> 125000 | O28: =CHOOSE(Drivers!$C$3,O35,O42,O49) -> 150000 | ... Q28: =CHOOSE(Drivers!$C$3,Q35,Q42,Q49) -> 200000
B30: Best case
B31: Tesla Model 3 | H31: =H38*105% -> 472500 | I31: =I38*105% -> 472500 | J31: =J38*105% -> 525000 | K31: =K38*105% -> 577500 | L31: =L38*105% -> 630000 | M31: =M38*105% -> 682500 | N31: =N38*105% -> 735000 | O31: =O38*105% -> 787500 | ... Q31: =Q38*105% -> 892500
B32: Tesla Model S and X | H32: =H39*105% -> 42000 | I32: =I39*105% -> 21000 | J32: =J39*105% -> 10500 | K32: =K39*105% -> 0 | L32: =L39*105% -> 0 | M32: =M39*105% -> 0 | N32: =N39*105% -> 0 | O32: =O39*105% -> 0 | ... Q32: =Q39*105% -> 0
B33: Tesla Model Y | H33: =H40*105% -> 1260000 | I33: =I40*105% -> 1417500 | J33: =J40*105% -> 1575000 | K33: =K40*105% -> 1732500 | L33: =L40*105% -> 1942500 | M33: =M40*105% -> 2100000 | N33: =N40*105% -> 2257500 | O33: =O40*105% -> 2415000 | ... Q33: =Q40*105% -> 2730000
B34: Tesla Cybertruck | H34: =H41*105% -> 78750 | I34: =I41*105% -> 126000 | J34: =J41*105% -> 189000 | K34: =K41*105% -> 262500 | L34: =L41*105% -> 315000 | M34: =M41*105% -> 367500 | N34: =N41*105% -> 420000 | O34: =O41*105% -> 472500 | ... Q34: =Q41*105% -> 577500
B35: Tesla Semi | H35: =H42*105% -> 10500 | I35: =I42*105% -> 21000 | J35: =J42*105% -> 36750 | K35: =K42*105% -> 52500 | L35: =L42*105% -> 78750 | M35: =M42*105% -> 105000 | N35: =N42*105% -> 131250 | O35: =O42*105% -> 157500 | ... Q35: =Q42*105% -> 210000
B37: Base case
B38: Tesla Model 3 | H38: 450000 | I38: 450000 | J38: 500000 | K38: 550000 | L38: 600000 | M38: 650000 | N38: 700000 | O38: 750000 | P38: 800000 | Q38: 850000
B39: Tesla Model S and X | H39: 40000 | I39: 20000 | J39: 10000 | K39: 0 | L39: 0 | M39: 0 | N39: 0 | O39: 0 | P39: 0 | Q39: 0
B40: Tesla Model Y | H40: 1200000 | I40: 1350000 | J40: 1500000 | K40: 1650000 | L40: 1850000 | M40: 2000000 | N40: 2150000 | O40: 2300000 | P40: 2450000 | Q40: 2600000
B41: Tesla Cybertruck | H41: 75000 | I41: 120000 | J41: 180000 | K41: 250000 | L41: 300000 | M41: 350000 | N41: 400000 | O41: 450000 | P41: 500000 | Q41: 550000
B42: Tesla Semi | H42: 10000 | I42: 20000 | J42: 35000 | K42: 50000 | L42: 75000 | M42: 100000 | N42: 125000 | O42: 150000 | P42: 175000 | Q42: 200000
B44: Worst case
B45: Tesla Model 3 | H45: =H38*95% -> 427500 | I45: =I38*95% -> 427500 | J45: =J38*95% -> 475000 | K45: =K38*95% -> 522500 | L45: =L38*95% -> 570000 | M45: =M38*95% -> 617500 | N45: =N38*95% -> 665000 | O45: =O38*95% -> 712500 | ... Q45: =Q38*95% -> 807500
B46: Tesla Model S and X | H46: =H39*95% -> 38000 | I46: =I39*95% -> 19000 | J46: =J39*95% -> 9500 | K46: =K39*95% -> 0 | L46: =L39*95% -> 0 | M46: =M39*95% -> 0 | N46: =N39*95% -> 0 | O46: =O39*95% -> 0 | ... Q46: =Q39*95% -> 0
B47: Tesla Cybertruck | H47: =H40*95% -> 1140000 | I47: =I40*95% -> 1282500 | J47: =J40*95% -> 1425000 | K47: =K40*95% -> 1567500 | L47: =L40*95% -> 1757500 | M47: =M40*95% -> 1900000 | N47: =N40*95% -> 2042500 | O47: =O40*95% -> 2185000 | ... Q47: =Q40*95% -> 2470000
B48: Tesla Pickup | H48: =H41*95% -> 71250 | I48: =I41*95% -> 114000 | J48: =J41*95% -> 171000 | K48: =K41*95% -> 237500 | L48: =L41*95% -> 285000 | M48: =M41*95% -> 332500 | N48: =N41*95% -> 380000 | O48: =O41*95% -> 427500 | ... Q48: =Q41*95% -> 522500
B49: Tesla Semi | H49: =H42*95% -> 9500 | I49: =I42*95% -> 19000 | J49: =J42*95% -> 33250 | K49: =K42*95% -> 47500 | L49: =L42*95% -> 71250 | M49: =M42*95% -> 95000 | N49: =N42*95% -> 118750 | O49: =O42*95% -> 142500 | ... Q49: =Q42*95% -> 190000

Sheet Deliveries development

Sheet Deliveries comparables
B1: Deliveries comparables
B3: Comparables 2021-2025
B6: Vehicle Sales 2021-2025 - average | C6: Average | D6: Adj. Average
B7: BYD (BEV only) | C7: 939000 | D7: =C7 -> 939000
B8: NIO | C8: 128000 | D8: =C8 -> 128000
B9: XPeng | C9: 115000 | D9: =C9 -> 115000
B10: Li Auto | C10: 226000 | D10: =C10 -> 226000
B11: Rivian | C11: 25000 | D11: =C11 -> 25000
B12: Lucid | C12: 4000 | D12: =C12 -> 4000
B13: Toyota | C13: 10100000 | D13: =C13 -> 10100000
B14: Volkswagen Group | C14: 8700000 | D14: =C14 -> 8700000
B15: Hyundai-Kia | C15: 6800000 | D15: =C15 -> 6800000
B16: General Motors | C16: 6100000 | D16: =C16 -> 6100000
B17: Ford | C17: 4300000 | D17: =C17 -> 4300000
B18: BMW | C18: 2300000 | D18: =C18 -> 2300000
B19: Mercedes-Benz | C19: 2100000 | D19: =C19 -> 2100000
B20: Ferrari | C20: n.a. | D20: n.a.
B21: Scania | C21: n.a. | D21: n.a.
B22: MAN | C22: n.a. | D22: n.a.
B23: Paccar | C23: n.a. | D23: n.a.
B24: Average | C24: n.a. | D24: =AVERAGE(D7:D23) -> 3218230.8
B28: Tesla Expected Deliveries
B29: 2026 | D29: =Deliveries!H$10 -> 1775000
B30: 2030 | D30: =Deliveries!L$10 -> 2825000
B31: 2035 | D31: =Deliveries!Q$10 -> 4200000

Sheet Average Prices
B1: Average prices
B3: Model and Version | C3: Range(max) | D3: Base price | E3: Fully loaded | F3: Average Price per Model
B4: Tesla Model 3 | C4: 466 miles | D4: 36990 | E4: 56990 | F4: =AVERAGE(D4:E4) -> 46990
B6: Tesla Model S | C6: 405 miles | D6: 94990 | E6: 111990 | F6: =AVERAGE(D6:E6) -> 103490
B7: Tesla Model X | C7: 348 miles | D7: 101630 | E7: 116990 | F7: =AVERAGE(D7:E7) -> 109310
B8: Tesla Model X & S | F8: =AVERAGE(F6:F7) -> 106400
B10: Tesla Model Y | C10: 357 miles | D10: 39990 | E10: 59990 | F10: =AVERAGE(D10:E10) -> 49990
B12: Tesla Cybertruck | C12: 340 miles | D12: 69990 | E12: 117999 | F12: =AVERAGE(D12:E12) -> 93994.5
B14: Tesla Semi | C14: 805 miles | D14: 260000 | E14: 290000 | F14: =AVERAGE(D14:E14) -> 275000

Sheet Automotive Revenue
B1: Revenue Automotive
C3: Tesla Revenue Automotive (in mln $)
B4: Vehicle | C4: 2021 Act | D4: 2022 Act | E4: 2023 Act | F4: 2024 Act | G4: 2025 Act | H4: 2026 Fcst | I4: 2027 Fcst | J4: 2028 Fcst | K4: 2029 Fcst | L4: 2030 Fcst | M4: 2031 Fcst | N4: 2032 Fcst | O4: 2033 Fcst | P4: 2034 Fcst | Q4: 2035 Fcst | R4: Average Price ($)
B5: Tesla Model 3 | C5: =($R5*Deliveries!C5)/1000000 -> 23495 | D5: =($R5*Deliveries!D5)/1000000 -> 24904.7 | E5: =($R5*Deliveries!E5)/1000000 -> 23495 | F5: =($R5*Deliveries!F5)/1000000 -> 22555.2 | G5: =($R5*Deliveries!G5)/1000000 -> 21145.5 | H5: =($R5*Deliveries!H5)*H15/1000000 -> 21145.5 | I5: =($R5*Deliveries!I5)*I15/1000000 -> 21145.5 | J5: =($R5*Deliveries!J5)*J15/1000000 -> 23495 | K5: =($R5*Deliveries!K5)*K15/1000000 -> 25844.5 | L5: =($R5*Deliveries!L5)*L15/1000000 -> 28194 | M5: =($R5*Deliveries!M5)*M15/1000000 -> 30543.5 | N5: =($R5*Deliveries!N5)*N15/1000000 -> 32893 | O5: =($R5*Deliveries!O5)*O15/1000000 -> 35242.5 | ... Q5: =($R5*Deliveries!Q5)*Q15/1000000 -> 39941.5 | R5: ='Average Prices'!F4 -> 46990
B6: Tesla Model S and X | C6: =($R6*Deliveries!C6)/1000000 -> 5320 | D6: =($R6*Deliveries!D6)/1000000 -> 7128.8 | E6: =($R6*Deliveries!E6)/1000000 -> 7341.6 | F6: =($R6*Deliveries!F6)/1000000 -> 5958.4 | G6: =($R6*Deliveries!G6)/1000000 -> 5320 | H6: =($R6*Deliveries!H6)*H16/1000000 -> 4256 | I6: =($R6*Deliveries!I6)*I16/1000000 -> 2128 | J6: =($R6*Deliveries!J6)*J16/1000000 -> 1064 | K6: =($R6*Deliveries!K6)*K16/1000000 -> 0 | L6: =($R6*Deliveries!L6)*L16/1000000 -> 0 | M6: =($R6*Deliveries!M6)*M16/1000000 -> 0 | N6: =($R6*Deliveries!N6)*N16/1000000 -> 0 | O6: =($R6*Deliveries!O6)*O16/1000000 -> 0 | ... Q6: =($R6*Deliveries!Q6)*Q16/1000000 -> 0 | R6: ='Average Prices'!F8 -> 106400
B7: Tesla Model Y | C7: =($R7*Deliveries!C7)/1000000 -> 20545.89 | D7: =($R7*Deliveries!D7)/1000000 -> 35842.83 | E7: =($R7*Deliveries!E7)/1000000 -> 56988.6 | F7: =($R7*Deliveries!F7)/1000000 -> 56188.76 | G7: =($R7*Deliveries!G7)/1000000 -> 56488.7 | H7: =($R7*Deliveries!H7)*H17/1000000 -> 59988 | I7: =($R7*Deliveries!I7)*I17/1000000 -> 67486.5 | J7: =($R7*Deliveries!J7)*J17/1000000 -> 74985 | K7: =($R7*Deliveries!K7)*K17/1000000 -> 82483.5 | L7: =($R7*Deliveries!L7)*L17/1000000 -> 92481.5 | M7: =($R7*Deliveries!M7)*M17/1000000 -> 99980 | N7: =($R7*Deliveries!N7)*N17/1000000 -> 107478.5 | O7: =($R7*Deliveries!O7)*O17/1000000 -> 114977 | ... Q7: =($R7*Deliveries!Q7)*Q17/1000000 -> 129974 | R7: ='Average Prices'!F10 -> 49990
B8: Tesla Cybertruck | C8: =($R8*Deliveries!C8)/1000000 -> 0 | D8: =($R8*Deliveries!D8)/1000000 -> 0 | E8: =($R8*Deliveries!E8)/1000000 -> 84.59505 | F8: =($R8*Deliveries!F8)/1000000 -> 1785.8955 | G8: =($R8*Deliveries!G8)/1000000 -> 4699.725 | H8: =($R8*Deliveries!H8)*H18/1000000 -> 7049.5875 | I8: =($R8*Deliveries!I8)*I18/1000000 -> 11279.34 | J8: =($R8*Deliveries!J8)*J18/1000000 -> 16919.01 | K8: =($R8*Deliveries!K8)*K18/1000000 -> 23498.625 | L8: =($R8*Deliveries!L8)*L18/1000000 -> 28198.35 | M8: =($R8*Deliveries!M8)*M18/1000000 -> 32898.075 | N8: =($R8*Deliveries!N8)*N18/1000000 -> 37597.8 | O8: =($R8*Deliveries!O8)*O18/1000000 -> 42297.525 | ... Q8: =($R8*Deliveries!Q8)*Q18/1000000 -> 51696.975 | R8: ='Average Prices'!F12 -> 93994.5
B9: Tesla Semi | C9: =($R9*Deliveries!C9)/1000000 -> 0 | D9: =($R9*Deliveries!D9)/1000000 -> 24.75 | E9: =($R9*Deliveries!E9)/1000000 -> 49.5 | F9: =($R9*Deliveries!F9)/1000000 -> 79.75 | G9: =($R9*Deliveries!G9)/1000000 -> 1375 | H9: =($R9*Deliveries!H9)*H19/1000000 -> 2750 | I9: =($R9*Deliveries!I9)*I19/1000000 -> 5500 | J9: =($R9*Deliveries!J9)*J19/1000000 -> 9625 | K9: =($R9*Deliveries!K9)*K19/1000000 -> 13750 | L9: =($R9*Deliveries!L9)*L19/1000000 -> 20625 | M9: =($R9*Deliveries!M9)*M19/1000000 -> 27500 | N9: =($R9*Deliveries!N9)*N19/1000000 -> 34375 | O9: =($R9*Deliveries!O9)*O19/1000000 -> 41250 | ... Q9: =($R9*Deliveries!Q9)*Q19/1000000 -> 55000 | R9: ='Average Prices'!F14 -> 275000
B10: Total | C10: ='P&L Input'!C4 -> 47232 | D10: ='P&L Input'!D4 -> 71462 | E10: ='P&L Input'!E4 -> 82419 | F10: ='P&L Input'!F4 -> 77070 | G10: ='P&L Input'!G4 -> 69526 | H10: =SUM(H5:H9) -> 95189.087 | I10: =SUM(I5:I9) -> 107539.34 | J10: =SUM(J5:J9) -> 126088.01 | K10: =SUM(K5:K9) -> 145576.62 | L10: =SUM(L5:L9) -> 169498.85 | M10: =SUM(M5:M9) -> 190921.58 | N10: =SUM(N5:N9) -> 212344.3 | O10: =SUM(O5:O9) -> 233767.02 | ... Q10: =SUM(Q5:Q9) -> 276612.47
B14: Selected case
B15: Tesla Model 3 | H15: =CHOOSE(Drivers!$C$3,'Automotive Revenue'!H22,'Automotive Revenue'!H29,'Automotive Revenue'!H36) -> 1 | I15: =CHOOSE(Drivers!$C$3,'Automotive Revenue'!I22,'Automotive Revenue'!I29,'Automotive Revenue'!I36) -> 1 | J15: =CHOOSE(Drivers!$C$3,'Automotive Revenue'!J22,'Automotive Revenue'!J29,'Automotive Revenue'!J36) -> 1 | K15: =CHOOSE(Drivers!$C$3,'Automotive Revenue'!K22,'Automotive Revenue'!K29,'Automotive Revenue'!K36) -> 1 | L15: =CHOOSE(Drivers!$C$3,'Automotive Revenue'!L22,'Automotive Revenue'!L29,'Automotive Revenue'!L36) -> 1 | M15: =CHOOSE(Drivers!$C$3,'Automotive Revenue'!M22,'Automotive Revenue'!M29,'Automotive Revenue'!M36) -> 1 | N15: =CHOOSE(Drivers!$C$3,'Automotive Revenue'!N22,'Automotive Revenue'!N29,'Automotive Revenue'!N36) -> 1 | O15: =CHOOSE(Drivers!$C$3,'Automotive Revenue'!O22,'Automotive Revenue'!O29,'Automotive Revenue'!O36) -> 1 | ... Q15: =CHOOSE(Drivers!$C$3,'Automotive Revenue'!Q22,'Automotive Revenue'!Q29,'Automotive Revenue'!Q36) -> 1
B16: Tesla Model S and X | H16: =CHOOSE(Drivers!$C$3,'Automotive Revenue'!H23,'Automotive Revenue'!H30,'Automotive Revenue'!H37) -> 1 | I16: =CHOOSE(Drivers!$C$3,'Automotive Revenue'!I23,'Automotive Revenue'!I30,'Automotive Revenue'!I37) -> 1 | J16: =CHOOSE(Drivers!$C$3,'Automotive Revenue'!J23,'Automotive Revenue'!J30,'Automotive Revenue'!J37) -> 1 | K16: =CHOOSE(Drivers!$C$3,'Automotive Revenue'!K23,'Automotive Revenue'!K30,'Automotive Revenue'!K37) -> 1 | L16: =CHOOSE(Drivers!$C$3,'Automotive Revenue'!L23,'Automotive Revenue'!L30,'Automotive Revenue'!L37) -> 1 | M16: =CHOOSE(Drivers!$C$3,'Automotive Revenue'!M23,'Automotive Revenue'!M30,'Automotive Revenue'!M37) -> 1 | N16: =CHOOSE(Drivers!$C$3,'Automotive Revenue'!N23,'Automotive Revenue'!N30,'Automotive Revenue'!N37) -> 1 | O16: =CHOOSE(Drivers!$C$3,'Automotive Revenue'!O23,'Automotive Revenue'!O30,'Automotive Revenue'!O37) -> 1 | ... Q16: =CHOOSE(Drivers!$C$3,'Automotive Revenue'!Q23,'Automotive Revenue'!Q30,'Automotive Revenue'!Q37) -> 1
B17: Tesla Model Y | H17: =CHOOSE(Drivers!$C$3,'Automotive Revenue'!H24,'Automotive Revenue'!H31,'Automotive Revenue'!H38) -> 1 | I17: =CHOOSE(Drivers!$C$3,'Automotive Revenue'!I24,'Automotive Revenue'!I31,'Automotive Revenue'!I38) -> 1 | J17: =CHOOSE(Drivers!$C$3,'Automotive Revenue'!J24,'Automotive Revenue'!J31,'Automotive Revenue'!J38) -> 1 | K17: =CHOOSE(Drivers!$C$3,'Automotive Revenue'!K24,'Automotive Revenue'!K31,'Automotive Revenue'!K38) -> 1 | L17: =CHOOSE(Drivers!$C$3,'Automotive Revenue'!L24,'Automotive Revenue'!L31,'Automotive Revenue'!L38) -> 1 | M17: =CHOOSE(Drivers!$C$3,'Automotive Revenue'!M24,'Automotive Revenue'!M31,'Automotive Revenue'!M38) -> 1 | N17: =CHOOSE(Drivers!$C$3,'Automotive Revenue'!N24,'Automotive Revenue'!N31,'Automotive Revenue'!N38) -> 1 | O17: =CHOOSE(Drivers!$C$3,'Automotive Revenue'!O24,'Automotive Revenue'!O31,'Automotive Revenue'!O38) -> 1 | ... Q17: =CHOOSE(Drivers!$C$3,'Automotive Revenue'!Q24,'Automotive Revenue'!Q31,'Automotive Revenue'!Q38) -> 1
B18: Tesla Cybertruck | H18: =CHOOSE(Drivers!$C$3,'Automotive Revenue'!H25,'Automotive Revenue'!H32,'Automotive Revenue'!H39) -> 1 | I18: =CHOOSE(Drivers!$C$3,'Automotive Revenue'!I25,'Automotive Revenue'!I32,'Automotive Revenue'!I39) -> 1 | J18: =CHOOSE(Drivers!$C$3,'Automotive Revenue'!J25,'Automotive Revenue'!J32,'Automotive Revenue'!J39) -> 1 | K18: =CHOOSE(Drivers!$C$3,'Automotive Revenue'!K25,'Automotive Revenue'!K32,'Automotive Revenue'!K39) -> 1 | L18: =CHOOSE(Drivers!$C$3,'Automotive Revenue'!L25,'Automotive Revenue'!L32,'Automotive Revenue'!L39) -> 1 | M18: =CHOOSE(Drivers!$C$3,'Automotive Revenue'!M25,'Automotive Revenue'!M32,'Automotive Revenue'!M39) -> 1 | N18: =CHOOSE(Drivers!$C$3,'Automotive Revenue'!N25,'Automotive Revenue'!N32,'Automotive Revenue'!N39) -> 1 | O18: =CHOOSE(Drivers!$C$3,'Automotive Revenue'!O25,'Automotive Revenue'!O32,'Automotive Revenue'!O39) -> 1 | ... Q18: =CHOOSE(Drivers!$C$3,'Automotive Revenue'!Q25,'Automotive Revenue'!Q32,'Automotive Revenue'!Q39) -> 1
B19: Tesla Semi | H19: =CHOOSE(Drivers!$C$3,'Automotive Revenue'!H26,'Automotive Revenue'!H33,'Automotive Revenue'!H40) -> 1 | I19: =CHOOSE(Drivers!$C$3,'Automotive Revenue'!I26,'Automotive Revenue'!I33,'Automotive Revenue'!I40) -> 1 | J19: =CHOOSE(Drivers!$C$3,'Automotive Revenue'!J26,'Automotive Revenue'!J33,'Automotive Revenue'!J40) -> 1 | K19: =CHOOSE(Drivers!$C$3,'Automotive Revenue'!K26,'Automotive Revenue'!K33,'Automotive Revenue'!K40) -> 1 | L19: =CHOOSE(Drivers!$C$3,'Automotive Revenue'!L26,'Automotive Revenue'!L33,'Automotive Revenue'!L40) -> 1 | M19: =CHOOSE(Drivers!$C$3,'Automotive Revenue'!M26,'Automotive Revenue'!M33,'Automotive Revenue'!M40) -> 1 | N19: =CHOOSE(Drivers!$C$3,'Automotive Revenue'!N26,'Automotive Revenue'!N33,'Automotive Revenue'!N40) -> 1 | O19: =CHOOSE(Drivers!$C$3,'Automotive Revenue'!O26,'Automotive Revenue'!O33,'Automotive Revenue'!O40) -> 1 | ... Q19: =CHOOSE(Drivers!$C$3,'Automotive Revenue'!Q26,'Automotive Revenue'!Q33,'Automotive Revenue'!Q40) -> 1
B21: Best case
B22: Tesla Model 3 | H22: 1.02 | I22: 1.02 | J22: 1.02 | K22: 1.02 | L22: 1.02 | M22: 1.02 | N22: 1.02 | O22: 1.02 | P22: 1.02 | Q22: 1.02
B23: Tesla Model S and X | H23: 1.02 | I23: 1.02 | J23: 1.02 | K23: 1.02 | L23: 1.02 | M23: 1.02 | N23: 1.02 | O23: 1.02 | P23: 1.02 | Q23: 1.02
B24: Tesla Model Y | H24: 1.02 | I24: 1.02 | J24: 1.02 | K24: 1.02 | L24: 1.02 | M24: 1.02 | N24: 1.02 | O24: 1.02 | P24: 1.02 | Q24: 1.02
B25: Tesla Cybertruck | H25: 1.02 | I25: 1.02 | J25: 1.02 | K25: 1.02 | L25: 1.02 | M25: 1.02 | N25: 1.02 | O25: 1.02 | P25: 1.02 | Q25: 1.02
B26: Tesla Semi | H26: 1.02 | I26: 1.02 | J26: 1.02 | K26: 1.02 | L26: 1.02 | M26: 1.02 | N26: 1.02 | O26: 1.02 | P26: 1.02 | Q26: 1.02
B28: Base case
B29: Tesla Model 3 | H29: 1 | I29: 1 | J29: 1 | K29: 1 | L29: 1 | M29: 1 | N29: 1 | O29: 1 | P29: 1 | Q29: 1
B30: Tesla Model S and X | H30: 1 | I30: 1 | J30: 1 | K30: 1 | L30: 1 | M30: 1 | N30: 1 | O30: 1 | P30: 1 | Q30: 1
B31: Tesla Model Y | H31: 1 | I31: 1 | J31: 1 | K31: 1 | L31: 1 | M31: 1 | N31: 1 | O31: 1 | P31: 1 | Q31: 1
B32: Tesla Cybertruck | H32: 1 | I32: 1 | J32: 1 | K32: 1 | L32: 1 | M32: 1 | N32: 1 | O32: 1 | P32: 1 | Q32: 1
B33: Tesla Semi | H33: 1 | I33: 1 | J33: 1 | K33: 1 | L33: 1 | M33: 1 | N33: 1 | O33: 1 | P33: 1 | Q33: 1
B35: Worst case
B36: Tesla Model 3 | H36: 0.98 | I36: 0.98 | J36: 0.98 | K36: 0.98 | L36: 0.98 | M36: 0.98 | N36: 0.98 | O36: 0.98 | P36: 0.98 | Q36: 0.98
B37: Tesla Model S and X | H37: 0.98 | I37: 0.98 | J37: 0.98 | K37: 0.98 | L37: 0.98 | M37: 0.98 | N37: 0.98 | O37: 0.98 | P37: 0.98 | Q37: 0.98
B38: Tesla Model Y | H38: 0.98 | I38: 0.98 | J38: 0.98 | K38: 0.98 | L38: 0.98 | M38: 0.98 | N38: 0.98 | O38: 0.98 | P38: 0.98 | Q38: 0.98
B39: Tesla Cybertruck | H39: 0.98 | I39: 0.98 | J39: 0.98 | K39: 0.98 | L39: 0.98 | M39: 0.98 | N39: 0.98 | O39: 0.98 | P39: 0.98 | Q39: 0.98
B40: Tesla Semi | H40: 0.98 | I40: 0.98 | J40: 0.98 | K40: 0.98 | L40: 0.98 | M40: 0.98 | N40: 0.98 | O40: 0.98 | P40: 0.98 | Q40: 0.98

Sheet Automotive Gross Margin
B1: GP %
B3: Comparables 2019
B5: Vehicle | C5: Comparable companies | D5: GP % Comp. 1 | E5: GP % Comp. 2 | F5: GP % Comp. 3 | H5: Average
B6: Tesla Model 3 | C6: GM, Ford, Fiat Chrysler | D6: 0.18 | E6: =(((155900-134693)/155900)+((160338-136269)/160338))/2 -> 0.14307182 | F6: =(((108187-93164)/108187)+((110412-95011)/110412))/2 -> 0.13917403 | H6: =C15 -> 0.18 | I6: Historic
B7: Tesla Model S and X | C7: BMW, Mercedes Cars, Volkswagen | D7: 0.19 | E7: =((33067/167362)+(29165/172745))/2 -> 0.18320519 | F7: 0.172 | H7: =C16 -> 0.19 | I7: Historic
B8: Tesla Model Y | C8: GM, Ford, Fiat Chrysler | D8: 0.13 | E8: =(((155900-134693)/155900)+((160338-136269)/160338))/2 -> 0.14307182 | F8: =(((108187-93164)/108187)+((110412-95011)/110412))/2 -> 0.13917403 | H8: =C17 -> 0.2 | I8: Historic
B9: Tesla Pickup | C9: GM, Ford, Fiat Chrysler | D9: 0.14 | E9: =(((155900-134693)/155900)+((160338-136269)/160338))/2 -> 0.14307182 | F9: =F6 -> 0.13917403 | H9: =C18 -> 0.12 | I9: Historic
B10: Tesla Semi | C10: Scania, MAN, Paccar | D10: 0.15 | E10: =E7 -> 0.18320519 | F10: =(((24120-20556)/24120)+((22139-18925)/22139))/2 -> 0.14646743 | H10: =C19 -> 0.15 | I10: Historic
B12: Historical
B14: Vehicle | C14: Historic Average GP%
B15: Tesla Model 3 | C15: 0.18
B16: Tesla Model S and X | C16: 0.19
B17: Tesla Model Y | C17: 0.2
B18: Tesla Pickup | C18: 0.12
B19: Tesla Semi | C19: 0.15

Sheet Automotive Gross Profit
B1: Gross Profit
B3: ($ millions) | C3: Tesla Gross Profit (in mln $)
B4: Vehicle | C4: 2021 Act | D4: 2022 Act | E4: 2023 Act | F4: 2024 Act | G4: 2025 Act | H4: 2026 Fcst | I4: 2027 Fcst | J4: 2028 Fcst | K4: 2029 Fcst | L4: 2030 Fcst | M4: 2031 Fcst | N4: 2032 Fcst | O4: 2033 Fcst | P4: 2034 Fcst | Q4: 2035 Fcst
B5: Tesla Model 3 | C5: n.a. | D5: n.a. | E5: n.a. | F5: n.a. | G5: n.a. | H5: =H13*'Automotive Revenue'!H5 -> 3806.19 | I5: =I13*'Automotive Revenue'!I5 -> 3806.19 | J5: =J13*'Automotive Revenue'!J5 -> 4229.1 | K5: =K13*'Automotive Revenue'!K5 -> 4652.01 | L5: =L13*'Automotive Revenue'!L5 -> 5074.92 | M5: =M13*'Automotive Revenue'!M5 -> 5497.83 | N5: =N13*'Automotive Revenue'!N5 -> 5920.74 | O5: =O13*'Automotive Revenue'!O5 -> 6343.65 | ... Q5: =Q13*'Automotive Revenue'!Q5 -> 7189.47
B6: Tesla Model S and X | C6: n.a. | D6: n.a. | E6: n.a. | F6: n.a. | G6: n.a. | H6: =H14*'Automotive Revenue'!H6 -> 808.64 | I6: =I14*'Automotive Revenue'!I6 -> 404.32 | J6: =J14*'Automotive Revenue'!J6 -> 202.16 | K6: =K14*'Automotive Revenue'!K6 -> 0 | L6: =L14*'Automotive Revenue'!L6 -> 0 | M6: =M14*'Automotive Revenue'!M6 -> 0 | N6: =N14*'Automotive Revenue'!N6 -> 0 | O6: =O14*'Automotive Revenue'!O6 -> 0 | ... Q6: =Q14*'Automotive Revenue'!Q6 -> 0
B7: Tesla Model Y | C7: n.a. | D7: n.a. | E7: n.a. | F7: n.a. | G7: n.a. | H7: =H15*'Automotive Revenue'!H7 -> 11997.6 | I7: =I15*'Automotive Revenue'!I7 -> 13497.3 | J7: =J15*'Automotive Revenue'!J7 -> 14997 | K7: =K15*'Automotive Revenue'!K7 -> 16496.7 | L7: =L15*'Automotive Revenue'!L7 -> 18496.3 | M7: =M15*'Automotive Revenue'!M7 -> 19996 | N7: =N15*'Automotive Revenue'!N7 -> 21495.7 | O7: =O15*'Automotive Revenue'!O7 -> 22995.4 | ... Q7: =Q15*'Automotive Revenue'!Q7 -> 25994.8
B8: Tesla Pickup | C8: 0 | D8: 0 | E8: n.a. | F8: n.a. | G8: n.a. | H8: =H16*'Automotive Revenue'!H8 -> 845.9505 | I8: =I16*'Automotive Revenue'!I8 -> 1353.5208 | J8: =J16*'Automotive Revenue'!J8 -> 2030.2812 | K8: =K16*'Automotive Revenue'!K8 -> 2819.835 | L8: =L16*'Automotive Revenue'!L8 -> 3383.802 | M8: =M16*'Automotive Revenue'!M8 -> 3947.769 | N8: =N16*'Automotive Revenue'!N8 -> 4511.736 | O8: =O16*'Automotive Revenue'!O8 -> 5075.703 | ... Q8: =Q16*'Automotive Revenue'!Q8 -> 6203.637
B9: Tesla Semi | C9: 0 | D9: n.a. | E9: n.a. | F9: n.a. | G9: n.a. | H9: =H17*'Automotive Revenue'!H9 -> 412.5 | I9: =I17*'Automotive Revenue'!I9 -> 825 | J9: =J17*'Automotive Revenue'!J9 -> 1443.75 | K9: =K17*'Automotive Revenue'!K9 -> 2062.5 | L9: =L17*'Automotive Revenue'!L9 -> 3093.75 | M9: =M17*'Automotive Revenue'!M9 -> 4125 | N9: =N17*'Automotive Revenue'!N9 -> 5156.25 | O9: =O17*'Automotive Revenue'!O9 -> 6187.5 | ... Q9: =Q17*'Automotive Revenue'!Q9 -> 8250
B10: Total | C10: =('P&L Input'!C4+'P&L Input'!C8) -> 13839 | D10: =('P&L Input'!D4+'P&L Input'!D8) -> 20354 | E10: =('P&L Input'!E4+'P&L Input'!E8) -> 16030 | F10: =('P&L Input'!F4+'P&L Input'!F8) -> 14197 | G10: =('P&L Input'!G4+'P&L Input'!G8) -> 12361 | H10: =SUM(H5:H9) -> 17870.88 | I10: =SUM(I5:I9) -> 19886.331 | J10: =SUM(J5:J9) -> 22902.291 | K10: =SUM(K5:K9) -> 26031.045 | L10: =SUM(L5:L9) -> 30048.772 | M10: =SUM(M5:M9) -> 33566.599 | N10: =SUM(N5:N9) -> 37084.426 | O10: =SUM(O5:O9) -> 40602.253 | ... Q10: =SUM(Q5:Q9) -> 47637.907
B12: Selected case
B13: Tesla Model 3 | G13: =CHOOSE(Drivers!$C$3,'Automotive Gross Profit'!G20,'Automotive Gross Profit'!G27,'Automotive Gross Profit'!G34) -> 0.18 | H13: =CHOOSE(Drivers!$C$3,'Automotive Gross Profit'!H20,'Automotive Gross Profit'!H27,'Automotive Gross Profit'!H34) -> 0.18 | I13: =CHOOSE(Drivers!$C$3,'Automotive Gross Profit'!I20,'Automotive Gross Profit'!I27,'Automotive Gross Profit'!I34) -> 0.18 | J13: =CHOOSE(Drivers!$C$3,'Automotive Gross Profit'!J20,'Automotive Gross Profit'!J27,'Automotive Gross Profit'!J34) -> 0.18 | K13: =CHOOSE(Drivers!$C$3,'Automotive Gross Profit'!K20,'Automotive Gross Profit'!K27,'Automotive Gross Profit'!K34) -> 0.18 | L13: =CHOOSE(Drivers!$C$3,'Automotive Gross Profit'!L20,'Automotive Gross Profit'!L27,'Automotive Gross Profit'!L34) -> 0.18 | M13: =CHOOSE(Drivers!$C$3,'Automotive Gross Profit'!M20,'Automotive Gross Profit'!M27,'Automotive Gross Profit'!M34) -> 0.18 | N13: =CHOOSE(Drivers!$C$3,'Automotive Gross Profit'!N20,'Automotive Gross Profit'!N27,'Automotive Gross Profit'!N34) -> 0.18 | ... Q13: =CHOOSE(Drivers!$C$3,'Automotive Gross Profit'!Q20,'Automotive Gross Profit'!Q27,'Automotive Gross Profit'!Q34) -> 0.18
B14: Tesla Model S and X | G14: =CHOOSE(Drivers!$C$3,'Automotive Gross Profit'!G21,'Automotive Gross Profit'!G28,'Automotive Gross Profit'!G35) -> 0.19 | H14: =CHOOSE(Drivers!$C$3,'Automotive Gross Profit'!H21,'Automotive Gross Profit'!H28,'Automotive Gross Profit'!H35) -> 0.19 | I14: =CHOOSE(Drivers!$C$3,'Automotive Gross Profit'!I21,'Automotive Gross Profit'!I28,'Automotive Gross Profit'!I35) -> 0.19 | J14: =CHOOSE(Drivers!$C$3,'Automotive Gross Profit'!J21,'Automotive Gross Profit'!J28,'Automotive Gross Profit'!J35) -> 0.19 | K14: =CHOOSE(Drivers!$C$3,'Automotive Gross Profit'!K21,'Automotive Gross Profit'!K28,'Automotive Gross Profit'!K35) -> 0.19 | L14: =CHOOSE(Drivers!$C$3,'Automotive Gross Profit'!L21,'Automotive Gross Profit'!L28,'Automotive Gross Profit'!L35) -> 0.19 | M14: =CHOOSE(Drivers!$C$3,'Automotive Gross Profit'!M21,'Automotive Gross Profit'!M28,'Automotive Gross Profit'!M35) -> 0.19 | N14: =CHOOSE(Drivers!$C$3,'Automotive Gross Profit'!N21,'Automotive Gross Profit'!N28,'Automotive Gross Profit'!N35) -> 0.19 | ... Q14: =CHOOSE(Drivers!$C$3,'Automotive Gross Profit'!Q21,'Automotive Gross Profit'!Q28,'Automotive Gross Profit'!Q35) -> 0.19
B15: Tesla Model Y | G15: =CHOOSE(Drivers!$C$3,'Automotive Gross Profit'!G22,'Automotive Gross Profit'!G29,'Automotive Gross Profit'!G36) -> 0.2 | H15: =CHOOSE(Drivers!$C$3,'Automotive Gross Profit'!H22,'Automotive Gross Profit'!H29,'Automotive Gross Profit'!H36) -> 0.2 | I15: =CHOOSE(Drivers!$C$3,'Automotive Gross Profit'!I22,'Automotive Gross Profit'!I29,'Automotive Gross Profit'!I36) -> 0.2 | J15: =CHOOSE(Drivers!$C$3,'Automotive Gross Profit'!J22,'Automotive Gross Profit'!J29,'Automotive Gross Profit'!J36) -> 0.2 | K15: =CHOOSE(Drivers!$C$3,'Automotive Gross Profit'!K22,'Automotive Gross Profit'!K29,'Automotive Gross Profit'!K36) -> 0.2 | L15: =CHOOSE(Drivers!$C$3,'Automotive Gross Profit'!L22,'Automotive Gross Profit'!L29,'Automotive Gross Profit'!L36) -> 0.2 | M15: =CHOOSE(Drivers!$C$3,'Automotive Gross Profit'!M22,'Automotive Gross Profit'!M29,'Automotive Gross Profit'!M36) -> 0.2 | N15: =CHOOSE(Drivers!$C$3,'Automotive Gross Profit'!N22,'Automotive Gross Profit'!N29,'Automotive Gross Profit'!N36) -> 0.2 | ... Q15: =CHOOSE(Drivers!$C$3,'Automotive Gross Profit'!Q22,'Automotive Gross Profit'!Q29,'Automotive Gross Profit'!Q36) -> 0.2
B16: Tesla Pickup | G16: =CHOOSE(Drivers!$C$3,'Automotive Gross Profit'!G23,'Automotive Gross Profit'!G30,'Automotive Gross Profit'!G37) -> 0.12 | H16: =CHOOSE(Drivers!$C$3,'Automotive Gross Profit'!H23,'Automotive Gross Profit'!H30,'Automotive Gross Profit'!H37) -> 0.12 | I16: =CHOOSE(Drivers!$C$3,'Automotive Gross Profit'!I23,'Automotive Gross Profit'!I30,'Automotive Gross Profit'!I37) -> 0.12 | J16: =CHOOSE(Drivers!$C$3,'Automotive Gross Profit'!J23,'Automotive Gross Profit'!J30,'Automotive Gross Profit'!J37) -> 0.12 | K16: =CHOOSE(Drivers!$C$3,'Automotive Gross Profit'!K23,'Automotive Gross Profit'!K30,'Automotive Gross Profit'!K37) -> 0.12 | L16: =CHOOSE(Drivers!$C$3,'Automotive Gross Profit'!L23,'Automotive Gross Profit'!L30,'Automotive Gross Profit'!L37) -> 0.12 | M16: =CHOOSE(Drivers!$C$3,'Automotive Gross Profit'!M23,'Automotive Gross Profit'!M30,'Automotive Gross Profit'!M37) -> 0.12 | N16: =CHOOSE(Drivers!$C$3,'Automotive Gross Profit'!N23,'Automotive Gross Profit'!N30,'Automotive Gross Profit'!N37) -> 0.12 | ... Q16: =CHOOSE(Drivers!$C$3,'Automotive Gross Profit'!Q23,'Automotive Gross Profit'!Q30,'Automotive Gross Profit'!Q37) -> 0.12
B17: Tesla Semi | G17: =CHOOSE(Drivers!$C$3,'Automotive Gross Profit'!G24,'Automotive Gross Profit'!G31,'Automotive Gross Profit'!G38) -> 0.15 | H17: =CHOOSE(Drivers!$C$3,'Automotive Gross Profit'!H24,'Automotive Gross Profit'!H31,'Automotive Gross Profit'!H38) -> 0.15 | I17: =CHOOSE(Drivers!$C$3,'Automotive Gross Profit'!I24,'Automotive Gross Profit'!I31,'Automotive Gross Profit'!I38) -> 0.15 | J17: =CHOOSE(Drivers!$C$3,'Automotive Gross Profit'!J24,'Automotive Gross Profit'!J31,'Automotive Gross Profit'!J38) -> 0.15 | K17: =CHOOSE(Drivers!$C$3,'Automotive Gross Profit'!K24,'Automotive Gross Profit'!K31,'Automotive Gross Profit'!K38) -> 0.15 | L17: =CHOOSE(Drivers!$C$3,'Automotive Gross Profit'!L24,'Automotive Gross Profit'!L31,'Automotive Gross Profit'!L38) -> 0.15 | M17: =CHOOSE(Drivers!$C$3,'Automotive Gross Profit'!M24,'Automotive Gross Profit'!M31,'Automotive Gross Profit'!M38) -> 0.15 | N17: =CHOOSE(Drivers!$C$3,'Automotive Gross Profit'!N24,'Automotive Gross Profit'!N31,'Automotive Gross Profit'!N38) -> 0.15 | ... Q17: =CHOOSE(Drivers!$C$3,'Automotive Gross Profit'!Q24,'Automotive Gross Profit'!Q31,'Automotive Gross Profit'!Q38) -> 0.15
B19: Best case
B20: Tesla Model 3 | G20: =G27+1.5% -> 0.195 | H20: =H27+1.5% -> 0.195 | I20: =I27+1.5% -> 0.195 | J20: =J27+1.5% -> 0.195 | K20: =K27+1.5% -> 0.195 | L20: =L27+1.5% -> 0.195 | M20: =M27+1.5% -> 0.195 | N20: =N27+1.5% -> 0.195 | ... Q20: =Q27+1.5% -> 0.195
B21: Tesla Model S and X | G21: =G28+1.5% -> 0.205 | H21: =H28+1.5% -> 0.205 | I21: =I28+1.5% -> 0.205 | J21: =J28+1.5% -> 0.205 | K21: =K28+1.5% -> 0.205 | L21: =L28+1.5% -> 0.205 | M21: =M28+1.5% -> 0.205 | N21: =N28+1.5% -> 0.205 | ... Q21: =Q28+1.5% -> 0.205
B22: Tesla Model Y | G22: =G29+1.5% -> 0.215 | H22: =H29+1.5% -> 0.215 | I22: =I29+1.5% -> 0.215 | J22: =J29+1.5% -> 0.215 | K22: =K29+1.5% -> 0.215 | L22: =L29+1.5% -> 0.215 | M22: =M29+1.5% -> 0.215 | N22: =N29+1.5% -> 0.215 | ... Q22: =Q29+1.5% -> 0.215
B23: Tesla Pickup | G23: =G30+1.5% -> 0.135 | H23: =H30+1.5% -> 0.135 | I23: =I30+1.5% -> 0.135 | J23: =J30+1.5% -> 0.135 | K23: =K30+1.5% -> 0.135 | L23: =L30+1.5% -> 0.135 | M23: =M30+1.5% -> 0.135 | N23: =N30+1.5% -> 0.135 | ... Q23: =Q30+1.5% -> 0.135
B24: Tesla Semi | G24: =G31+1.5% -> 0.165 | H24: =H31+1.5% -> 0.165 | I24: =I31+1.5% -> 0.165 | J24: =J31+1.5% -> 0.165 | K24: =K31+1.5% -> 0.165 | L24: =L31+1.5% -> 0.165 | M24: =M31+1.5% -> 0.165 | N24: =N31+1.5% -> 0.165 | ... Q24: =Q31+1.5% -> 0.165
B26: Base case
B27: Tesla Model 3 | G27: ='Automotive Gross Margin'!$H6 -> 0.18 | H27: ='Automotive Gross Margin'!$H6 -> 0.18 | I27: ='Automotive Gross Margin'!$H6 -> 0.18 | J27: ='Automotive Gross Margin'!$H6 -> 0.18 | K27: ='Automotive Gross Margin'!$H6 -> 0.18 | L27: ='Automotive Gross Margin'!$H6 -> 0.18 | M27: ='Automotive Gross Margin'!$H6 -> 0.18 | N27: ='Automotive Gross Margin'!$H6 -> 0.18 | ... Q27: ='Automotive Gross Margin'!$H6 -> 0.18
B28: Tesla Model S and X | G28: ='Automotive Gross Margin'!$H7 -> 0.19 | H28: ='Automotive Gross Margin'!$H7 -> 0.19 | I28: ='Automotive Gross Margin'!$H7 -> 0.19 | J28: ='Automotive Gross Margin'!$H7 -> 0.19 | K28: ='Automotive Gross Margin'!$H7 -> 0.19 | L28: ='Automotive Gross Margin'!$H7 -> 0.19 | M28: ='Automotive Gross Margin'!$H7 -> 0.19 | N28: ='Automotive Gross Margin'!$H7 -> 0.19 | ... Q28: ='Automotive Gross Margin'!$H7 -> 0.19
B29: Tesla Model Y | G29: ='Automotive Gross Margin'!$H8 -> 0.2 | H29: ='Automotive Gross Margin'!$H8 -> 0.2 | I29: ='Automotive Gross Margin'!$H8 -> 0.2 | J29: ='Automotive Gross Margin'!$H8 -> 0.2 | K29: ='Automotive Gross Margin'!$H8 -> 0.2 | L29: ='Automotive Gross Margin'!$H8 -> 0.2 | M29: ='Automotive Gross Margin'!$H8 -> 0.2 | N29: ='Automotive Gross Margin'!$H8 -> 0.2 | ... Q29: ='Automotive Gross Margin'!$H8 -> 0.2
B30: Tesla Pickup | G30: ='Automotive Gross Margin'!$H9 -> 0.12 | H30: ='Automotive Gross Margin'!$H9 -> 0.12 | I30: ='Automotive Gross Margin'!$H9 -> 0.12 | J30: ='Automotive Gross Margin'!$H9 -> 0.12 | K30: ='Automotive Gross Margin'!$H9 -> 0.12 | L30: ='Automotive Gross Margin'!$H9 -> 0.12 | M30: ='Automotive Gross Margin'!$H9 -> 0.12 | N30: ='Automotive Gross Margin'!$H9 -> 0.12 | ... Q30: ='Automotive Gross Margin'!$H9 -> 0.12
B31: Tesla Semi | G31: ='Automotive Gross Margin'!$H10 -> 0.15 | H31: ='Automotive Gross Margin'!$H10 -> 0.15 | I31: ='Automotive Gross Margin'!$H10 -> 0.15 | J31: ='Automotive Gross Margin'!$H10 -> 0.15 | K31: ='Automotive Gross Margin'!$H10 -> 0.15 | L31: ='Automotive Gross Margin'!$H10 -> 0.15 | M31: ='Automotive Gross Margin'!$H10 -> 0.15 | N31: ='Automotive Gross Margin'!$H10 -> 0.15 | ... Q31: ='Automotive Gross Margin'!$H10 -> 0.15
B33: Worst case
B34: Tesla Model 3 | G34: =G27-1.5% -> 0.165 | H34: =H27-1.5% -> 0.165 | I34: =I27-1.5% -> 0.165 | J34: =J27-1.5% -> 0.165 | K34: =K27-1.5% -> 0.165 | L34: =L27-1.5% -> 0.165 | M34: =M27-1.5% -> 0.165 | N34: =N27-1.5% -> 0.165 | ... Q34: =Q27-1.5% -> 0.165
B35: Tesla Model S and X | G35: =G28-1.5% -> 0.175 | H35: =H28-1.5% -> 0.175 | I35: =I28-1.5% -> 0.175 | J35: =J28-1.5% -> 0.175 | K35: =K28-1.5% -> 0.175 | L35: =L28-1.5% -> 0.175 | M35: =M28-1.5% -> 0.175 | N35: =N28-1.5% -> 0.175 | ... Q35: =Q28-1.5% -> 0.175
B36: Tesla Model Y | G36: =G29-1.5% -> 0.185 | H36: =H29-1.5% -> 0.185 | I36: =I29-1.5% -> 0.185 | J36: =J29-1.5% -> 0.185 | K36: =K29-1.5% -> 0.185 | L36: =L29-1.5% -> 0.185 | M36: =M29-1.5% -> 0.185 | N36: =N29-1.5% -> 0.185 | ... Q36: =Q29-1.5% -> 0.185
B37: Tesla Pickup | G37: =G30-1.5% -> 0.105 | H37: =H30-1.5% -> 0.105 | I37: =I30-1.5% -> 0.105 | J37: =J30-1.5% -> 0.105 | K37: =K30-1.5% -> 0.105 | L37: =L30-1.5% -> 0.105 | M37: =M30-1.5% -> 0.105 | N37: =N30-1.5% -> 0.105 | ... Q37: =Q30-1.5% -> 0.105
B38: Tesla Semi | G38: =G31-1.5% -> 0.135 | H38: =H31-1.5% -> 0.135 | I38: =I31-1.5% -> 0.135 | J38: =J31-1.5% -> 0.135 | K38: =K31-1.5% -> 0.135 | L38: =L31-1.5% -> 0.135 | M38: =M31-1.5% -> 0.135 | N38: =N31-1.5% -> 0.135 | ... Q38: =Q31-1.5% -> 0.135

Sheet Cost of sales automotive
B1: Cost of sales automotive
B3: ($ millions) | C3: Tesla Cost of sales (in mln $)
B4: Vehicle | C4: 2021 Act | D4: 2022 Act | E4: 2023 Act | F4: 2024 Act | G4: 2025 Act | H4: 2026 Fcst | I4: 2027 Fcst | J4: 2028 Fcst | K4: 2029 Fcst | L4: 2030 Fcst | M4: 2031 Fcst | N4: 2032 Fcst | O4: 2033 Fcst | P4: 2034 Fcst | Q4: 2035 Fcst
B5: Tesla Model 3 | C5: n.a. | D5: n.a. | E5: n.a. | F5: n.a. | G5: n.a. | H5: =-('Automotive Revenue'!H5-'Automotive Gross Profit'!H5) -> -17339.31 | I5: =-('Automotive Revenue'!I5-'Automotive Gross Profit'!I5) -> -17339.31 | J5: =-('Automotive Revenue'!J5-'Automotive Gross Profit'!J5) -> -19265.9 | K5: =-('Automotive Revenue'!K5-'Automotive Gross Profit'!K5) -> -21192.49 | L5: =-('Automotive Revenue'!L5-'Automotive Gross Profit'!L5) -> -23119.08 | M5: =-('Automotive Revenue'!M5-'Automotive Gross Profit'!M5) -> -25045.67 | N5: =-('Automotive Revenue'!N5-'Automotive Gross Profit'!N5) -> -26972.26 | O5: =-('Automotive Revenue'!O5-'Automotive Gross Profit'!O5) -> -28898.85 | ... Q5: =-('Automotive Revenue'!Q5-'Automotive Gross Profit'!Q5) -> -32752.03
B6: Tesla Model S and X | C6: n.a. | D6: n.a. | E6: n.a. | F6: n.a. | G6: n.a. | H6: =-('Automotive Revenue'!H6-'Automotive Gross Profit'!H6) -> -3447.36 | I6: =-('Automotive Revenue'!I6-'Automotive Gross Profit'!I6) -> -1723.68 | J6: =-('Automotive Revenue'!J6-'Automotive Gross Profit'!J6) -> -861.84 | K6: =-('Automotive Revenue'!K6-'Automotive Gross Profit'!K6) -> 0 | L6: =-('Automotive Revenue'!L6-'Automotive Gross Profit'!L6) -> 0 | M6: =-('Automotive Revenue'!M6-'Automotive Gross Profit'!M6) -> 0 | N6: =-('Automotive Revenue'!N6-'Automotive Gross Profit'!N6) -> 0 | O6: =-('Automotive Revenue'!O6-'Automotive Gross Profit'!O6) -> 0 | ... Q6: =-('Automotive Revenue'!Q6-'Automotive Gross Profit'!Q6) -> 0
B7: Tesla Model Y | C7: n.a. | D7: n.a. | E7: n.a. | F7: n.a. | G7: n.a. | H7: =-('Automotive Revenue'!H7-'Automotive Gross Profit'!H7) -> -47990.4 | I7: =-('Automotive Revenue'!I7-'Automotive Gross Profit'!I7) -> -53989.2 | J7: =-('Automotive Revenue'!J7-'Automotive Gross Profit'!J7) -> -59988 | K7: =-('Automotive Revenue'!K7-'Automotive Gross Profit'!K7) -> -65986.8 | L7: =-('Automotive Revenue'!L7-'Automotive Gross Profit'!L7) -> -73985.2 | M7: =-('Automotive Revenue'!M7-'Automotive Gross Profit'!M7) -> -79984 | N7: =-('Automotive Revenue'!N7-'Automotive Gross Profit'!N7) -> -85982.8 | O7: =-('Automotive Revenue'!O7-'Automotive Gross Profit'!O7) -> -91981.6 | ... Q7: =-('Automotive Revenue'!Q7-'Automotive Gross Profit'!Q7) -> -103979.2
B8: Tesla Pickup | C8: 0 | D8: 0 | E8: n.a. | F8: n.a. | G8: n.a. | H8: =-('Automotive Revenue'!H8-'Automotive Gross Profit'!H8) -> -6203.637 | I8: =-('Automotive Revenue'!I8-'Automotive Gross Profit'!I8) -> -9925.8192 | J8: =-('Automotive Revenue'!J8-'Automotive Gross Profit'!J8) -> -14888.729 | K8: =-('Automotive Revenue'!K8-'Automotive Gross Profit'!K8) -> -20678.79 | L8: =-('Automotive Revenue'!L8-'Automotive Gross Profit'!L8) -> -24814.548 | M8: =-('Automotive Revenue'!M8-'Automotive Gross Profit'!M8) -> -28950.306 | N8: =-('Automotive Revenue'!N8-'Automotive Gross Profit'!N8) -> -33086.064 | O8: =-('Automotive Revenue'!O8-'Automotive Gross Profit'!O8) -> -37221.822 | ... Q8: =-('Automotive Revenue'!Q8-'Automotive Gross Profit'!Q8) -> -45493.338
B9: Tesla Semi | C9: 0 | D9: n.a. | E9: n.a. | F9: n.a. | G9: n.a. | H9: =-('Automotive Revenue'!H9-'Automotive Gross Profit'!H9) -> -2337.5 | I9: =-('Automotive Revenue'!I9-'Automotive Gross Profit'!I9) -> -4675 | J9: =-('Automotive Revenue'!J9-'Automotive Gross Profit'!J9) -> -8181.25 | K9: =-('Automotive Revenue'!K9-'Automotive Gross Profit'!K9) -> -11687.5 | L9: =-('Automotive Revenue'!L9-'Automotive Gross Profit'!L9) -> -17531.25 | M9: =-('Automotive Revenue'!M9-'Automotive Gross Profit'!M9) -> -23375 | N9: =-('Automotive Revenue'!N9-'Automotive Gross Profit'!N9) -> -29218.75 | O9: =-('Automotive Revenue'!O9-'Automotive Gross Profit'!O9) -> -35062.5 | ... Q9: =-('Automotive Revenue'!Q9-'Automotive Gross Profit'!Q9) -> -46750
B10: Total | C10: =-('Automotive Revenue'!C10-'Automotive Gross Profit'!C10) -> -33393 | D10: =-('Automotive Revenue'!D10-'Automotive Gross Profit'!D10) -> -51108 | E10: =-('Automotive Revenue'!E10-'Automotive Gross Profit'!E10) -> -66389 | F10: =-('Automotive Revenue'!F10-'Automotive Gross Profit'!F10) -> -62873 | G10: =-('Automotive Revenue'!G10-'Automotive Gross Profit'!G10) -> -57165 | H10: =SUM(H5:H9) -> -77318.207 | I10: =SUM(I5:I9) -> -87653.009 | J10: =SUM(J5:J9) -> -103185.72 | K10: =SUM(K5:K9) -> -119545.58 | L10: =SUM(L5:L9) -> -139450.08 | M10: =SUM(M5:M9) -> -157354.98 | N10: =SUM(N5:N9) -> -175259.87 | O10: =SUM(O5:O9) -> -193164.77 | ... Q10: =SUM(Q5:Q9) -> -228974.57

Sheet Automotive Revenue and GP 
B1: Revenue and Gross Profit automotive
B2: ($ millions)
B3: Vehicle | C3: 2021 Act | D3: 2022 Act | E3: 2023 Act | F3: 2024 Act | G3: 2025 Act | H3: 2026 Fcst | I3: 2027 Fcst | J3: 2028 Fcst | K3: 2029 Fcst | L3: 2030 Fcst | M3: 2031 Fcst | N3: 2032 Fcst | O3: 2033 Fcst | P3: 2034 Fcst | Q3: 2035 Fcst
B4: Revenue automotive | C4: ='Automotive Revenue'!C10 -> 47232 | D4: ='Automotive Revenue'!D10 -> 71462 | E4: ='Automotive Revenue'!E10 -> 82419 | F4: ='Automotive Revenue'!F10 -> 77070 | G4: ='Automotive Revenue'!G10 -> 69526 | H4: ='Automotive Revenue'!H10 -> 95189.087 | I4: ='Automotive Revenue'!I10 -> 107539.34 | J4: ='Automotive Revenue'!J10 -> 126088.01 | ... Q4: ='Automotive Revenue'!Q10 -> 276612.47
B5: Gross Profit automotive | C5: ='Automotive Gross Profit'!C10 -> 13839 | D5: ='Automotive Gross Profit'!D10 -> 20354 | E5: ='Automotive Gross Profit'!E10 -> 16030 | F5: ='Automotive Gross Profit'!F10 -> 14197 | G5: ='Automotive Gross Profit'!G10 -> 12361 | H5: ='Automotive Gross Profit'!H10 -> 17870.88 | I5: ='Automotive Gross Profit'!I10 -> 19886.331 | J5: ='Automotive Gross Profit'!J10 -> 22902.291 | ... Q5: ='Automotive Gross Profit'!Q10 -> 47637.907
B6: GP% | C6: =C5/C4 -> 0.29300051 | D6: =D5/D4 -> 0.2848227 | E6: =E5/E4 -> 0.19449399 | F6: =F5/F4 -> 0.18420916 | G6: =G5/G4 -> 0.1777896 | H6: =H5/H4 -> 0.18774085 | I6: =I5/I4 -> 0.18492145 | J6: =J5/J4 -> 0.18163734 | ... Q6: =Q5/Q4 -> 0.17221894

Sheet Energy & Other
B14: Energy & Other

Sheet Revenue Energy & Other
B1: Revenue Energy & Other
C3: Tesla Revenue Energy & Other (in mln $)
B4: ($ millions) | C4: 2021 Act | D4: 2022 Act | E4: 2023 Act | F4: 2024 Act | G4: 2025 Act | H4: 2026 Fcst | I4: 2027 Fcst | J4: 2028 Fcst | K4: 2029 Fcst | L4: 2030 Fcst | M4: 2031 Fcst | N4: 2032 Fcst | O4: 2033 Fcst | P4: 2034 Fcst | Q4: 2035 Fcst
B5: Energy generation and storage | C5: ='P&L Input'!C5 -> 2789 | D5: ='P&L Input'!D5 -> 3909 | E5: ='P&L Input'!E5 -> 6035 | F5: ='P&L Input'!F5 -> 10086 | G5: ='P&L Input'!G5 -> 12771 | H5: n.a. | I5: n.a. | J5: n.a. | K5: n.a. | L5: n.a. | M5: n.a. | N5: n.a. | O5: n.a. | P5: n.a. | Q5: n.a.
B6: Services and other | C6: ='P&L Input'!C6 -> 3802 | D6: ='P&L Input'!D6 -> 6091 | E6: ='P&L Input'!E6 -> 8319 | F6: ='P&L Input'!F6 -> 10534 | G6: ='P&L Input'!G6 -> 12530 | H6: n.a. | I6: n.a. | J6: n.a. | K6: n.a. | L6: n.a. | M6: n.a. | N6: n.a. | O6: n.a. | P6: n.a. | Q6: n.a.
B7: Total Energy and Other | C7: =SUM(C5:C6) -> 6591 | D7: =SUM(D5:D6) -> 10000 | E7: =SUM(E5:E6) -> 14354 | F7: =SUM(F5:F6) -> 20620 | G7: =SUM(G5:G6) -> 25301 | H7: =G7*(1+H10) -> 29855.18 | I7: =H7*(1+I10) -> 33437.802 | J7: =I7*(1+J10) -> 36112.826 | K7: =J7*(1+K10) -> 38279.595 | L7: =K7*(1+L10) -> 40576.371 | M7: =L7*(1+M10) -> 43010.953 | N7: =M7*(1+N10) -> 45591.61 | O7: =N7*(1+O10) -> 48327.107 | ... Q7: =P7*(1+Q10) -> 54300.338
B9: Selected case
B10: Total Energy and Other | H10: =CHOOSE(Drivers!$C$3,'Revenue Energy & Other'!H14,'Revenue Energy & Other'!H17,'Revenue Energy & Other'!H20) -> 0.18 | I10: =CHOOSE(Drivers!$C$3,'Revenue Energy & Other'!I14,'Revenue Energy & Other'!I17,'Revenue Energy & Other'!I20) -> 0.12 | J10: =CHOOSE(Drivers!$C$3,'Revenue Energy & Other'!J14,'Revenue Energy & Other'!J17,'Revenue Energy & Other'!J20) -> 0.08 | K10: =CHOOSE(Drivers!$C$3,'Revenue Energy & Other'!K14,'Revenue Energy & Other'!K17,'Revenue Energy & Other'!K20) -> 0.06 | L10: =CHOOSE(Drivers!$C$3,'Revenue Energy & Other'!L14,'Revenue Energy & Other'!L17,'Revenue Energy & Other'!L20) -> 0.06 | M10: =CHOOSE(Drivers!$C$3,'Revenue Energy & Other'!M14,'Revenue Energy & Other'!M17,'Revenue Energy & Other'!M20) -> 0.06 | N10: =CHOOSE(Drivers!$C$3,'Revenue Energy & Other'!N14,'Revenue Energy & Other'!N17,'Revenue Energy & Other'!N20) -> 0.06 | O10: =CHOOSE(Drivers!$C$3,'Revenue Energy & Other'!O14,'Revenue Energy & Other'!O17,'Revenue Energy & Other'!O20) -> 0.06 | ... Q10: =CHOOSE(Drivers!$C$3,'Revenue Energy & Other'!Q14,'Revenue Energy & Other'!Q17,'Revenue Energy & Other'!Q20) -> 0.06
B12: Y-o-Y %
B13: Best case
B14: Total Energy and Other | H14: =H17+Drivers!$C$13 -> 0.211 | I14: =I17+Drivers!$C$13 -> 0.151 | J14: =J17+Drivers!$C$13 -> 0.111 | K14: =K17+Drivers!$C$13 -> 0.091 | L14: =L17+Drivers!$C$13 -> 0.091 | M14: =M17+Drivers!$C$13 -> 0.091 | N14: =N17+Drivers!$C$13 -> 0.091 | O14: =O17+Drivers!$C$13 -> 0.091 | ... Q14: =Q17+Drivers!$C$13 -> 0.091
B16: Base case
B17: Total Energy and Other | D17: =D7/C7-1 -> 0.51722045 | E17: =E7/D7-1 -> 0.4354 | F17: =F7/E7-1 -> 0.43653337 | G17: =G7/F7-1 -> 0.22701261 | H17: 0.18 | I17: 0.12 | J17: 0.08 | K17: 0.06 | L17: 0.06 | M17: 0.06 | N17: 0.06 | O17: 0.06 | P17: 0.06 | Q17: 0.06
B19: Worst case
B20: Total Energy and Other | H20: =H17-Drivers!$C$13 -> 0.149 | I20: =I17-Drivers!$C$13 -> 0.089 | J20: =J17-Drivers!$C$13 -> 0.049 | K20: =K17-Drivers!$C$13 -> 0.029 | L20: =L17-Drivers!$C$13 -> 0.029 | M20: =M17-Drivers!$C$13 -> 0.029 | N20: =N17-Drivers!$C$13 -> 0.029 | O20: =O17-Drivers!$C$13 -> 0.029 | ... Q20: =Q17-Drivers!$C$13 -> 0.029

Sheet Gross Profit Energy & Other
B1: Gross Profit Energy & Other
C3: Tesla GP% Energy and Other (in mln $)
B4: ($ millions) | C4: 2021 Act | D4: 2022 Act | E4: 2023 Act | F4: 2024 Act | G4: 2025 Act | H4: 2026 Fcst | I4: 2027 Fcst | J4: 2028 Fcst | K4: 2029 Fcst | L4: 2030 Fcst | M4: 2031 Fcst | N4: 2032 Fcst | O4: 2033 Fcst | P4: 2034 Fcst | Q4: 2035 Fcst
B5: Energy generation and storage | C5: =('P&L Input'!C5+'P&L Input'!C9) -> -129 | D5: =('P&L Input'!D5+'P&L Input'!D9) -> 288 | E5: =('P&L Input'!E5+'P&L Input'!E9) -> 1141 | F5: =('P&L Input'!F5+'P&L Input'!F9) -> 2640 | G5: =('P&L Input'!G5+'P&L Input'!G9) -> 3802 | H5: n.a. | I5: n.a. | J5: n.a. | K5: n.a. | L5: n.a. | M5: n.a. | N5: n.a. | O5: n.a. | P5: n.a. | Q5: n.a.
B6: Services and other | C6: =('P&L Input'!C6+'P&L Input'!C10) -> -104 | D6: =('P&L Input'!D6+'P&L Input'!D10) -> 211 | E6: =('P&L Input'!E6+'P&L Input'!E10) -> 489 | F6: =('P&L Input'!F6+'P&L Input'!F10) -> 613 | G6: =('P&L Input'!G6+'P&L Input'!G10) -> 931 | H6: n.a. | I6: n.a. | J6: n.a. | K6: n.a. | L6: n.a. | M6: n.a. | N6: n.a. | O6: n.a. | P6: n.a. | Q6: n.a.
B7: Total Energy and Other | C7: =SUM(C5:C6) -> -233 | D7: =SUM(D5:D6) -> 499 | E7: =SUM(E5:E6) -> 1630 | F7: =SUM(F5:F6) -> 3253 | G7: =SUM(G5:G6) -> 4733 | H7: =H11*'Revenue Energy & Other'!H7 -> 3390.2705 | I7: =I11*'Revenue Energy & Other'!I7 -> 3797.103 | J7: =J11*'Revenue Energy & Other'!J7 -> 4100.8713 | K7: =K11*'Revenue Energy & Other'!K7 -> 4346.9235 | L7: =L11*'Revenue Energy & Other'!L7 -> 4607.7389 | M7: =M11*'Revenue Energy & Other'!M7 -> 4884.2033 | N7: =N11*'Revenue Energy & Other'!N7 -> 5177.2555 | O7: =O11*'Revenue Energy & Other'!O7 -> 5487.8908 | ... Q7: =Q11*'Revenue Energy & Other'!Q7 -> 6166.1941
B10: Selected case
